Output of Assignment 1, Part 2
file: test_sailors_orm.py

PS C:\Users\alira\Documents\College\Fall 2019\ECE 464> pytest
============================================================================================================================ test session starts =============================================================================================================================
platform win32 -- Python 3.6.7, pytest-5.2.1, py-1.8.0, pluggy-0.13.0
rootdir: C:\Users\alira\Documents\College\Fall 2019\ECE 464
collected 7 items

test_sailors_orm.py .......                                                                                                                                                                                                                                             [100%]

============================================================================================================================= 7 passed in 0.63s ==============================================================================================================================
Exception ignored in: <function _ConnectionRecord.checkout.<locals>.<lambda> at 0x000002160149CC80>
Traceback (most recent call last):
  File "c:\users\alira\appdata\local\programs\python\python36\lib\site-packages\sqlalchemy\pool\base.py", line 503, in <lambda>
  File "c:\users\alira\appdata\local\programs\python\python36\lib\site-packages\sqlalchemy\pool\base.py", line 689, in _finalize_fairy
  File "c:\users\alira\appdata\local\programs\python\python36\lib\logging\__init__.py", line 1336, in error
  File "c:\users\alira\appdata\local\programs\python\python36\lib\logging\__init__.py", line 1548, in isEnabledFor
TypeError: '>=' not supported between instances of 'int' and 'NoneType'
